Workbook

Sheet Index
B1: CONVERTIBLE NOTE VALUATION | Cytokinetics (CYTK) | 1.75% Notes due Oct 2031
B2: Sr no. | C2: Particulars
B3: {=_xlfn.SEQUENCE(COUNTA(C3:C16))} -> 1 | C3: Valuation Summary
B4: 2 | C4: Assumptions and Terms
B5: 3 | C5: Straight Bond
B6: 4 | C6: BSM Model
B7: 5 | C7: Binomial Model
B8: 6 | C8: Volatility
B9: 7 | C9: Key Financials
B10: 8 | C10: Credit Rating
B11: 9 | C11: Comparable Companies
B12: 10 | C12: Reference
I25: i

Sheet Valuation Summary
B2: CONVERTIBLE NOTE VALUATION | Cytokinetics (CYTK) | 1.75% Notes due Oct 2031
D3: USD Mn
B4: Particulars | C4: BSM Model | D4: Binomial Model
B5: Value of Straight Bond | C5: =('Straight Bond'!C33*'Assumptions and Terms'!C16)/(10^6) -> 570.73232 | D5: =('Straight Bond'!C33*'Assumptions and Terms'!C16)/(10^6) -> 570.73232
B6: Add : Conversion Option | C6: =(BSM!C20*'Assumptions and Terms'!C16)/(10^6) -> 472.13872 | D6: =((Binomial!C59)*'Assumptions and Terms'!C16)/(10^6) -> 425.13705
B7: Value of 2031 Convertible Note | C7: =SUM(C5:C6) -> 1042.871 | D7: =SUM(D5:D6) -> 995.86937
B8: Valuation as on March 31, 2026 (10K) | C8: 957.1
B9: Variance | C9: =C7/C8-1 -> 0.089615546 | D9: =D7/C8-1 -> 0.040507123
B10: Corroboration | D10: =C7/D7-1 -> 0.047196623
B12: Company Overview :
B13: Cytokinetics (Nasdaq: CYTK) is a specialty cardiovascular biopharmaceutical company focused on cardiac muscle dysfunction. Building on over 25 years of research in muscle biology, the company launched its first commercial product, MYQORZO (aficamten), in January 2026 for adults with symptomatic obstructive hypertrophic cardiomyopathy. MYQORZO has also received approval from the European Commission and China's NMPA, with a first European launch planned in Germany. The pipeline includes omecamtiv mecarbil, a cardiac myosin activator in Phase 3 development for heart failure.

Sheet Assumptions and Terms
B2: CONVERTIBLE NOTE VALUATION | Cytokinetics (CYTK) | 1.75% Notes due Oct 2031
B4: A. INSTRUMENT TERMS
B5: Isssue Size (USD Mn) | C5: 750 | D5: https://ir.cytokinetics.com/press-releases/press-release-details/2025/Cytokinetics-Announces-Pricing-of-Upsized-650-0-Million-Convertible-Senior-Notes-Offering-Refinances-a-Portion-of-2027-Convertible-Notes/default.aspx
B6: Face Value (USD per share) | C6: 1000
B7: Coupon Rate (annualized) | C7: 0.0175 | D7: CYTK 10-K Feb 26, 2026
B8: Coupon Frequency (per year) | C8: 2 | D8: Semi-annual payments
B9: Date of Issue | C9: 45916 | D9: September 16, 2025 Press release
B10: Valuation Date | C10: 46179
B11: Date of Maturity | C11: 48122
B12: Maturity (years from valuation date) | C12: =(C11-C10)/365 -> 5.3232877
B13: Conversion Price (USD per share) | C13: 68.42 | D13: CYTK 10-K Feb 26, 2026; Conversion can happen only if the share price is traded at 30% premium of conversion price
B14: Stock Price at Issuance (USD per share) | C14: 49.76 | D14: https://ir.cytokinetics.com/press-releases/press-release-details/2025/Cytokinetics-Announces-Pricing-of-Upsized-650-0-Million-Convertible-Senior-Notes-Offering-Refinances-a-Portion-of-2027-Convertible-Notes/default.aspx
B15: Conversion Ratio | C15: =C6/C13 -> 14.615609
B16: Number of Notes | C16: =C5*10^6/C6 -> 750000
B18: B. MARKET INPUTS
B19: Risk-Free Rate (annual) | C19: 0.0447 | D19: fred.stlouisfed.org/series/DGS10
B20: Credit Spread (annual) | C20: ='Straight Bond'!C16 -> 0.0298 | D20: spread based on derived credit rating
B21: Equity Volatility (annual) | C21: =Volatility!G3 -> 0.63884308 | D21: annualized volatility of CYTK
B22: Dividend Yield | C22: 0 | D22: CYTK pays no dividend
B23: Share price ($ per share) | C23: =Volatility!C3 -> 71.48 | D23: Adjusted close on June 5, 2026
B25: C. DERIVED INPUTS
B26: Discount Rate for Bond Floor | C26: ='Straight Bond'!C18 -> 0.0745745
B27: Coupon Payment ($) | C27: =C6*C7/C8 -> 8.75
B28: Number of Coupon Periods | C28: =C12*C8 -> 10.646575
B29: Binomial Steps (n) | C29: 11

Sheet Straight Bond
B2: CONVERTIBLE NOTE VALUATION | Cytokinetics (CYTK) | 1.75% Notes due Oct 2031
B4: STRAIGHT BOND VALUATION
B5: A. INSTRUMENT TERMS
B6: Face Value ($) | C6: ='Assumptions and Terms'!C6 -> 1000
B7: Annual Coupon Rate | C7: 0.0175
B8: Coupon Frequency (per year) | C8: 2
B9: Settlement / Issue Date | C9: ='Assumptions and Terms'!$C$9 -> 45916
B10: First Coupon Date | C10: 46113
B11: Maturity Date | C11: 48122
B12: Valuation Date | C12: 46179
B13: Semi-Annual Coupon ($) | C13: =C6*C7/C8 -> 8.75
B14: B. DISCOUNT RATE
B15: Risk-Free Rate (Rf) | C15: ='Assumptions and Terms'!C19 -> 0.0447
B16: Credit Spread (CS) | C16: 0.0298 | D16: Credit Rating derived at B; https://fred.stlouisfed.org/series/BAMLH0A2HYB; refer credit rating sheet
B17: Unrated Premium | C17: =C16*0.25% -> 7.45e-05 | D17: Since there is no specific credit rating for the bonds, adding a risk premium to the spread
B18: Discount Rate | C18: =SUM(C15:C17) -> 0.0745745
B19: C. CASH FLOW SCHEDULE
B20: Period | C20: Payment Date | D20: Days | E20: t (yrs) | F20: Coupon ($) | G20: Principal ($) | H20: Total CF ($) | I20: DF | J20: PV ($)
B21: 1 | C21: 46296 | D21: =C21-$C$12 -> 117 | E21: =D21/365 -> 0.32054795 | F21: =C13 -> 8.75 | G21: 0 | H21: =F21+G21 -> 8.75 | I21: =1/(1+C18)^E21 -> 0.97720841 | J21: =H21*I21 -> 8.5505736
B22: 2 | C22: 46478 | D22: =C22-$C$12 -> 299 | E22: =D22/365 -> 0.81917808 | F22: =C13 -> 8.75 | G22: 0 | H22: =F22+G22 -> 8.75 | I22: =1/(1+C18)^E22 -> 0.94278295 | J22: =H22*I22 -> 8.2493508
B23: 3 | C23: 46661 | D23: =C23-$C$12 -> 482 | E23: =D23/365 -> 1.3205479 | F23: =C13 -> 8.75 | G23: 0 | H23: =F23+G23 -> 8.75 | I23: =1/(1+C18)^E23 -> 0.90939103 | J23: =H23*I23 -> 7.9571715
B24: 4 | C24: 46844 | D24: =C24-$C$12 -> 665 | E24: =D24/365 -> 1.8219178 | F24: =C13 -> 8.75 | G24: 0 | H24: =F24+G24 -> 8.75 | I24: =1/(1+C18)^E24 -> 0.87718179 | J24: =H24*I24 -> 7.6753407
B25: 5 | C25: 47027 | D25: =C25-$C$12 -> 848 | E25: =D25/365 -> 2.3232877 | F25: =C13 -> 8.75 | G25: 0 | H25: =F25+G25 -> 8.75 | I25: =1/(1+C18)^E25 -> 0.84611336 | J25: =H25*I25 -> 7.4034919
B26: 6 | C26: 47209 | D26: =C26-$C$12 -> 1030 | E26: =D26/365 -> 2.8219178 | F26: =C13 -> 8.75 | G26: 0 | H26: =F26+G26 -> 8.75 | I26: =1/(1+C18)^E26 -> 0.81630617 | J26: =H26*I26 -> 7.142679
B27: 7 | C27: 47392 | D27: =C27-$C$12 -> 1213 | E27: =D27/365 -> 3.3232877 | F27: =C13 -> 8.75 | G27: 0 | H27: =F27+G27 -> 8.75 | I27: =1/(1+C18)^E27 -> 0.78739386 | J27: =H27*I27 -> 6.8896963
B28: 8 | C28: 47574 | D28: =C28-$C$12 -> 1395 | E28: =D28/365 -> 3.8219178 | F28: =C13 -> 8.75 | G28: 0 | H28: =F28+G28 -> 8.75 | I28: =1/(1+C18)^E28 -> 0.75965526 | J28: =H28*I28 -> 6.6469835
B29: 9 | C29: 47757 | D29: =C29-$C$12 -> 1578 | E29: =D29/365 -> 4.3232877 | F29: =C13 -> 8.75 | G29: 0 | H29: =F29+G29 -> 8.75 | I29: =1/(1+C18)^E29 -> 0.73274944 | J29: =H29*I29 -> 6.4115576
B30: 10 | C30: 47939 | D30: =C30-$C$12 -> 1760 | E30: =D30/365 -> 4.8219178 | F30: =C13 -> 8.75 | G30: 0 | H30: =F30+G30 -> 8.75 | I30: =1/(1+C18)^E30 -> 0.70693587 | J30: =H30*I30 -> 6.1856889
B31: 11 | C31: 48122 | D31: =C31-$C$12 -> 1943 | E31: =D31/365 -> 5.3232877 | F31: =C13 -> 8.75 | G31: =C6 -> 1000 | H31: =F31+G31 -> 1008.75 | I31: =1/(1+C18)^E31 -> 0.68189729 | J31: =H31*I31 -> 687.86389
B32: D. BOND FLOOR
B33: Bond Floor Clean Price ($) | C33: =SUM(J21:J31) -> 760.97642
B34: Accrued Interest ($) | C34: =C6*C7*66/365 -> 3.1643836
B35: Bond Floor Dirty Price ($) | C35: =C33+C34 -> 764.14081
B36: Bond Floor as % of Par | C36: =C33/C6 -> 0.76097642

Sheet BSM
B2: BLACK-SCHOLES-MERTON (BSM) Convertible Note Valuation · Cytokinetics 1.75% Notes due 2031
B4: A. BOND FLOOR : PV of Straight Debt Component
B5: Bond Floor ($) | C5: ='Straight Bond'!$C$33 -> 760.97642
B7: B. EMBEDDED CALL : BSM Formula
B8: Stock Price S ($) | C8: ='Assumptions and Terms'!$C$23 -> 71.48
B9: Strike / Conversion Price K ($) | C9: ='Assumptions and Terms'!C13 -> 68.42
B10: Time to Maturity T (years) | C10: ='Assumptions and Terms'!C12 -> 5.3232877
B11: Risk-Free Rate r | C11: ='Assumptions and Terms'!C19 -> 0.0447
B12: Volatility σ | C12: ='Assumptions and Terms'!C21 -> 0.63884308
B13: Dividend Yield q | C13: ='Assumptions and Terms'!C22 -> 0
B14: d1 | C14: =(LN(C8/C9)+(C11-C13+C12^2/2)*C10)/(C12*SQRT(C10)) -> 0.92809823 | D14: d1: (LN(S/K)+(r-q+vol^2/2)*T)/(vol*SQRT(T))
B15: d2 | C15: =C14-C12*SQRT(C10) -> -0.54585656 | D15: d2: d1 - vol*SQRT(T)
B16: N(d1) | C16: =NORMSDIST(C14) -> 0.82332169 | D16: Standard normal CDF of d1 (NORM.S.DIST)
B17: N(d2) | C17: =NORMSDIST(C15) -> 0.29258227 | D17: Standard normal CDF of d2
B18: BSM Call Value per share ($) | C18: =C8*EXP(-C13*C10)*C16-C9*EXP(-C11*C10)*C17 -> 43.071642 | D18: BSM Call: S*EXP(-q*T)*N(d1) - K*EXP(-r*T)*N(d2)
B19: Conversion Ratio | C19: ='Assumptions and Terms'!C15 -> 14.615609
B20: Option Value ($ per note) | C20: =C18*C19 -> 629.5183
B22: C. BSM TOTAL FAIR VALUE & COMPONENT SPLIT
B23: Bond Floor ($) | C23: =C5 -> 760.97642
B24: Embedded Option Value ($) | C24: =C20 -> 629.5183
B25: BSM Total Fair Value ($ per note) | C25: =C23+C24 -> 1390.4947
B26: Bond Floor (% of total) | C26: =C23/C25 -> 0.54727027
B27: Option Value (% of total) | C27: =C24/C25 -> 0.45272973
B29: BSM values the conversion option as a European call exercisable at maturity, with no path-dependent restrictions. The actual instrument is more restrictive: before July 1, 2031, the holder can convert only if the stock exceeds $88.95 (130% of the $68.42 conversion price) for 20 of 30 consecutive trading days. BSM does not capture this contingency and therefore overstates the option value. The binomial lattice on the next sheet applies the threshold condition at each node and provides a more accurate valuation.

Sheet Binomial
B2: Binomial Lattice Convertible Note Valuation · Cytokinetics 1.75% Notes due 2031
B5: A. Inputs:
B6: Time Zero Stock Price ($) | C6: ='Assumptions and Terms'!C23 -> 71.48
B7: Conversion Price (K) ($) | C7: ='Assumptions and Terms'!C13 -> 68.42
B8: Semi-Annual Coupon ($) | C8: ='Assumptions and Terms'!C27 -> 8.75
B9: Conversion Ratio | C9: ='Assumptions and Terms'!C15 -> 14.615609
B10: Time to Expiration (years) | C10: ='Assumptions and Terms'!C12 -> 5.3232877
B11: Number of Steps (n) | C11: 11
B12: Sigma (σ) | C12: ='Assumptions and Terms'!C21 -> 0.63884308
B13: Risk-Free Rate (Rf) | C13: ='Assumptions and Terms'!C19 -> 0.0447
B14: Total Discount Rate | C14: ='Straight Bond'!C18 -> 0.0745745
B15: Contingent Conv. Threshold ($) | C15: ='Assumptions and Terms'!C13*1.3 -> 88.946
B18: B. Output: Initial Calculations
B19: delta t (Δt) | C19: =$C$10/$C$11 -> 0.48393524 | D19: t / n
B20: u (up factor) | C20: =EXP($C$12*SQRT($C$19)) -> 1.5595762 | D20: EXP(σ × √Δt)
B21: d (down factor) | C21: =1/$C$20 -> 0.64119985 | D21: 1 / u
B22: Risk-Neutral Probability p | C22: =(EXP($C$13*$C$19)-$C$21)/($C$20-$C$21) -> 0.41450081 | D22: (EXP(rf×Δt) − d) / (u−d)
B23: 1−p | C23: =1-$C$22 -> 0.58549919
B24: exp(−disc × Δt) | C24: =EXP(-$C$14*$C$19) -> 0.96455422 | D24: Discount factor per step
C26: n=0 Jun-26 | D26: n=1 Oct-26 | E26: n=2 Apr-27 | F26: n=3 Oct-27 | G26: n=4 Apr-28 | H26: n=5 Oct-28 | I26: n=6 Apr-29 | J26: n=7 Oct-29 | K26: n=8 Apr-30 | L26: n=9 Oct-30 | M26: n=10 Apr-31 | N26: n=11 Oct-31
B27: d=0 | C27: =$C$6 -> 71.48 | D27: =C27*$C$20 -> 111.4785 | E27: =D27*$C$20 -> 173.85922 | F27: =E27*$C$20 -> 271.14669 | G27: =F27*$C$20 -> 422.87391 | H27: =G27*$C$20 -> 659.50408 | I27: =H27*$C$20 -> 1028.5468 | J27: =I27*$C$20 -> 1604.0971 | K27: =J27*$C$20 -> 2501.7116 | ... N27: =M27*$C$20 -> 9489.799
B28: d=1 | D28: =C27*$C$21 -> 45.832965 | E28: =D28*$C$20 -> 71.48 | F28: =E28*$C$20 -> 111.4785 | G28: =F28*$C$20 -> 173.85922 | H28: =G28*$C$20 -> 271.14669 | I28: =H28*$C$20 -> 422.87391 | J28: =I28*$C$20 -> 659.50408 | K28: =J28*$C$20 -> 1028.5468 | L28: =K28*$C$20 -> 1604.0971 | ... N28: =M28*$C$20 -> 3901.6098
B29: d=2 | E29: =D28*$C$21 -> 29.38809 | F29: =E29*$C$20 -> 45.832965 | G29: =F29*$C$20 -> 71.48 | H29: =G29*$C$20 -> 111.4785 | I29: =H29*$C$20 -> 173.85922 | J29: =I29*$C$20 -> 271.14669 | K29: =J29*$C$20 -> 422.87391 | L29: =K29*$C$20 -> 659.50408 | M29: =L29*$C$20 -> 1028.5468 | N29: =M29*$C$20 -> 1604.0971
B30: d=3 | F30: =E29*$C$21 -> 18.843639 | G30: =F30*$C$20 -> 29.38809 | H30: =G30*$C$20 -> 45.832965 | I30: =H30*$C$20 -> 71.48 | J30: =I30*$C$20 -> 111.4785 | K30: =J30*$C$20 -> 173.85922 | L30: =K30*$C$20 -> 271.14669 | M30: =L30*$C$20 -> 422.87391 | N30: =M30*$C$20 -> 659.50408
B31: d=4 | G31: =F30*$C$21 -> 12.082539 | H31: =G31*$C$20 -> 18.843639 | I31: =H31*$C$20 -> 29.38809 | J31: =I31*$C$20 -> 45.832965 | K31: =J31*$C$20 -> 71.48 | L31: =K31*$C$20 -> 111.4785 | M31: =L31*$C$20 -> 173.85922 | N31: =M31*$C$20 -> 271.14669
B32: d=5 | H32: =G31*$C$21 -> 7.7473219 | I32: =H32*$C$20 -> 12.082539 | J32: =I32*$C$20 -> 18.843639 | K32: =J32*$C$20 -> 29.38809 | L32: =K32*$C$20 -> 45.832965 | M32: =L32*$C$20 -> 71.48 | N32: =M32*$C$20 -> 111.4785
B33: d=6 | I33: =H32*$C$21 -> 4.9675817 | J33: =I33*$C$20 -> 7.7473219 | K33: =J33*$C$20 -> 12.082539 | L33: =K33*$C$20 -> 18.843639 | M33: =L33*$C$20 -> 29.38809 | N33: =M33*$C$20 -> 45.832965
B34: d=7 | J34: =I33*$C$21 -> 3.1852126 | K34: =J34*$C$20 -> 4.9675817 | L34: =K34*$C$20 -> 7.7473219 | M34: =L34*$C$20 -> 12.082539 | N34: =M34*$C$20 -> 18.843639
B35: d=8 | K35: =J34*$C$21 -> 2.0423579 | L35: =K35*$C$20 -> 3.1852126 | M35: =L35*$C$20 -> 4.9675817 | N35: =M35*$C$20 -> 7.7473219
B36: d=9 | L36: =K35*$C$21 -> 1.3095595 | M36: =L36*$C$20 -> 2.0423579 | N36: =M36*$C$20 -> 3.1852126
B37: d=10 | M37: =L36*$C$21 -> 0.83968939 | N37: =M37*$C$20 -> 1.3095595
B38: d=11 | N38: =M37*$C$21 -> 0.53840871
C41: n=0 Jun-26 | D41: n=1 Oct-26 | E41: n=2 Apr-27 | F41: n=3 Oct-27 | G41: n=4 Apr-28 | H41: n=5 Oct-28 | I41: n=6 Apr-29 | J41: n=7 Oct-29 | K41: n=8 Apr-30 | L41: n=9 Oct-30 | M41: n=10 Apr-31 | N41: n=11 Oct-31
B42: d=0 | C42: =IF(C27>$C$15,MAX(C27*$C$9,($C$24*($C$22*D42+$C$23*D43))),($C$24*($C$22*D42+$C$23*D43))) -> 1327.8258 | D42: =$C$8+IF(D27>$C$15,MAX(D27*$C$9,($C$24*($C$22*E42+$C$23*E43))),($C$24*($C$22*E42+$C$23*E43))) -> 1810.9559 | E42: =$C$8+IF(E27>$C$15,MAX(E27*$C$9,($C$24*($C$22*F42+$C$23*F43))),($C$24*($C$22*F42+$C$23*F43))) -> 2616.6173 | F42: =$C$8+IF(F27>$C$15,MAX(F27*$C$9,($C$24*($C$22*G42+$C$23*G43))),($C$24*($C$22*G42+$C$23*G43))) -> 3971.7241 | G42: =$C$8+IF(G27>$C$15,MAX(G27*$C$9,($C$24*($C$22*H42+$C$23*H43))),($C$24*($C$22*H42+$C$23*H43))) -> 6189.31 | H42: =$C$8+IF(H27>$C$15,MAX(H27*$C$9,($C$24*($C$22*I42+$C$23*I43))),($C$24*($C$22*I42+$C$23*I43))) -> 9647.804 | I42: =$C$8+IF(I27>$C$15,MAX(I27*$C$9,($C$24*($C$22*J42+$C$23*J43))),($C$24*($C$22*J42+$C$23*J43))) -> 15041.589 | J42: =$C$8+IF(J27>$C$15,MAX(J27*$C$9,($C$24*($C$22*K42+$C$23*K43))),($C$24*($C$22*K42+$C$23*K43))) -> 23453.607 | K42: =$C$8+IF(K27>$C$15,MAX(K27*$C$9,($C$24*($C$22*L42+$C$23*L43))),($C$24*($C$22*L42+$C$23*L43))) -> 36572.79 | ... M42: =$C$8+IF(M27>$C$15,MAX(M27*$C$9,($C$24*($C$22*N42+$C$23*N43))),($C$24*($C$22*N42+$C$23*N43))) -> 88942.653 | N42: =$C$8+MAX(N27*$C$9,1000) -> 138707.95
B43: d=1 | D43: =$C$8+IF(D28>$C$15,MAX(D28*$C$9,($C$24*($C$22*E43+$C$23*E44))),($C$24*($C$22*E43+$C$23*E44))) -> 1069.1365 | E43: =$C$8+IF(E28>$C$15,MAX(E28*$C$9,($C$24*($C$22*F43+$C$23*F44))),($C$24*($C$22*F43+$C$23*F44))) -> 1338.762 | F43: =$C$8+IF(F28>$C$15,MAX(F28*$C$9,($C$24*($C$22*G43+$C$23*G44))),($C$24*($C$22*G43+$C$23*G44))) -> 1806.0132 | G43: =$C$8+IF(G28>$C$15,MAX(G28*$C$9,($C$24*($C$22*H43+$C$23*H44))),($C$24*($C$22*H43+$C$23*H44))) -> 2609.3348 | H43: =$C$8+IF(H28>$C$15,MAX(H28*$C$9,($C$24*($C$22*I43+$C$23*I44))),($C$24*($C$22*I43+$C$23*I44))) -> 3971.7241 | I43: =$C$8+IF(I28>$C$15,MAX(I28*$C$9,($C$24*($C$22*J43+$C$23*J44))),($C$24*($C$22*J43+$C$23*J44))) -> 6189.31 | J43: =$C$8+IF(J28>$C$15,MAX(J28*$C$9,($C$24*($C$22*K43+$C$23*K44))),($C$24*($C$22*K43+$C$23*K44))) -> 9647.804 | K43: =$C$8+IF(K28>$C$15,MAX(K28*$C$9,($C$24*($C$22*L43+$C$23*L44))),($C$24*($C$22*L43+$C$23*L44))) -> 15041.589 | ... M43: =$C$8+IF(M28>$C$15,MAX(M28*$C$9,($C$24*($C$22*N43+$C$23*N44))),($C$24*($C$22*N43+$C$23*N44))) -> 36572.79 | N43: =$C$8+MAX(N28*$C$9,1000) -> 57033.155
B44: d=2 | E44: =$C$8+IF(E29>$C$15,MAX(E29*$C$9,($C$24*($C$22*F44+$C$23*F45))),($C$24*($C$22*F44+$C$23*F45))) -> 929.86633 | F44: =$C$8+IF(F29>$C$15,MAX(F29*$C$9,($C$24*($C$22*G44+$C$23*G45))),($C$24*($C$22*G44+$C$23*G45))) -> 1076.5067 | G44: =$C$8+IF(G29>$C$15,MAX(G29*$C$9,($C$24*($C$22*H44+$C$23*H45))),($C$24*($C$22*H44+$C$23*H45))) -> 1335.1655 | H44: =$C$8+IF(H29>$C$15,MAX(H29*$C$9,($C$24*($C$22*I44+$C$23*I45))),($C$24*($C$22*I44+$C$23*I45))) -> 1793.118 | I44: =$C$8+IF(I29>$C$15,MAX(I29*$C$9,($C$24*($C$22*J44+$C$23*J45))),($C$24*($C$22*J44+$C$23*J45))) -> 2595.0346 | J44: =$C$8+IF(J29>$C$15,MAX(J29*$C$9,($C$24*($C$22*K44+$C$23*K45))),($C$24*($C$22*K44+$C$23*K45))) -> 3971.7241 | K44: =$C$8+IF(K29>$C$15,MAX(K29*$C$9,($C$24*($C$22*L44+$C$23*L45))),($C$24*($C$22*L44+$C$23*L45))) -> 6189.31 | L44: =$C$8+IF(L29>$C$15,MAX(L29*$C$9,($C$24*($C$22*M44+$C$23*M45))),($C$24*($C$22*M44+$C$23*M45))) -> 9647.804 | M44: =$C$8+IF(M29>$C$15,MAX(M29*$C$9,($C$24*($C$22*N44+$C$23*N45))),($C$24*($C$22*N44+$C$23*N45))) -> 15041.589 | N44: =$C$8+MAX(N29*$C$9,1000) -> 23453.607
B45: d=3 | F45: =$C$8+IF(F30>$C$15,MAX(F30*$C$9,($C$24*($C$22*G45+$C$23*G46))),($C$24*($C$22*G45+$C$23*G46))) -> 868.9217 | G45: =$C$8+IF(G30>$C$15,MAX(G30*$C$9,($C$24*($C$22*H45+$C$23*H46))),($C$24*($C$22*H45+$C$23*H46))) -> 945.46296 | H45: =$C$8+IF(H30>$C$15,MAX(H30*$C$9,($C$24*($C$22*I45+$C$23*I46))),($C$24*($C$22*I45+$C$23*I46))) -> 1079.2674 | I45: =$C$8+IF(I30>$C$15,MAX(I30*$C$9,($C$24*($C$22*J45+$C$23*J46))),($C$24*($C$22*J45+$C$23*J46))) -> 1322.4555 | J45: =$C$8+IF(J30>$C$15,MAX(J30*$C$9,($C$24*($C$22*K45+$C$23*K46))),($C$24*($C$22*K45+$C$23*K46))) -> 1767.7965 | K45: =$C$8+IF(K30>$C$15,MAX(K30*$C$9,($C$24*($C$22*L45+$C$23*L46))),($C$24*($C$22*L45+$C$23*L46))) -> 2570.7054 | L45: =$C$8+IF(L30>$C$15,MAX(L30*$C$9,($C$24*($C$22*M45+$C$23*M46))),($C$24*($C$22*M45+$C$23*M46))) -> 3971.7241 | M45: =$C$8+IF(M30>$C$15,MAX(M30*$C$9,($C$24*($C$22*N45+$C$23*N46))),($C$24*($C$22*N45+$C$23*N46))) -> 6189.31 | N45: =$C$8+MAX(N30*$C$9,1000) -> 9647.804
B46: d=4 | G46: =$C$8+IF(G31>$C$15,MAX(G31*$C$9,($C$24*($C$22*H46+$C$23*H47))),($C$24*($C$22*H46+$C$23*H47))) -> 853.77817 | H46: =$C$8+IF(H31>$C$15,MAX(H31*$C$9,($C$24*($C$22*I46+$C$23*I47))),($C$24*($C$22*I46+$C$23*I47))) -> 894.58433 | I46: =$C$8+IF(I31>$C$15,MAX(I31*$C$9,($C$24*($C$22*J46+$C$23*J47))),($C$24*($C$22*J46+$C$23*J47))) -> 959.3494 | J46: =$C$8+IF(J31>$C$15,MAX(J31*$C$9,($C$24*($C$22*K46+$C$23*K47))),($C$24*($C$22*K46+$C$23*K47))) -> 1074.6879 | K46: =$C$8+IF(K31>$C$15,MAX(K31*$C$9,($C$24*($C$22*L46+$C$23*L47))),($C$24*($C$22*L46+$C$23*L47))) -> 1294.8423 | L46: =$C$8+IF(L31>$C$15,MAX(L31*$C$9,($C$24*($C$22*M46+$C$23*M47))),($C$24*($C$22*M46+$C$23*M47))) -> 1724.7165 | M46: =$C$8+IF(M31>$C$15,MAX(M31*$C$9,($C$24*($C$22*N46+$C$23*N47))),($C$24*($C$22*N46+$C$23*N47))) -> 2549.8084 | N46: =$C$8+MAX(N31*$C$9,1000) -> 3971.7241
B47: d=5 | H47: =$C$8+IF(H32>$C$15,MAX(H32*$C$9,($C$24*($C$22*I47+$C$23*I48))),($C$24*($C$22*I47+$C$23*I48))) -> 862.98263 | I47: =$C$8+IF(I32>$C$15,MAX(I32*$C$9,($C$24*($C$22*J47+$C$23*J48))),($C$24*($C$22*J47+$C$23*J48))) -> 889.38838 | J47: =$C$8+IF(J32>$C$15,MAX(J32*$C$9,($C$24*($C$22*K47+$C$23*K48))),($C$24*($C$22*K47+$C$23*K48))) -> 922.41517 | K47: =$C$8+IF(K32>$C$15,MAX(K32*$C$9,($C$24*($C$22*L47+$C$23*L48))),($C$24*($C$22*L47+$C$23*L48))) -> 970.78909 | L47: =$C$8+IF(L32>$C$15,MAX(L32*$C$9,($C$24*($C$22*M47+$C$23*M48))),($C$24*($C$22*M47+$C$23*M48))) -> 1056.2912 | M47: =$C$8+IF(M32>$C$15,MAX(M32*$C$9,($C$24*($C$22*N47+$C$23*N48))),($C$24*($C$22*N47+$C$23*N48))) -> 1233.3541 | N47: =$C$8+MAX(N32*$C$9,1000) -> 1638.0763
B48: d=6 | I48: =$C$8+IF(I33>$C$15,MAX(I33*$C$9,($C$24*($C$22*J48+$C$23*J49))),($C$24*($C$22*J48+$C$23*J49))) -> 882.95949 | J48: =$C$8+IF(J33>$C$15,MAX(J33*$C$9,($C$24*($C$22*K48+$C$23*K49))),($C$24*($C$22*K48+$C$23*K49))) -> 906.33525 | K48: =$C$8+IF(K33>$C$15,MAX(K33*$C$9,($C$24*($C$22*L48+$C$23*L49))),($C$24*($C$22*L48+$C$23*L49))) -> 930.57003 | L48: =$C$8+IF(L33>$C$15,MAX(L33*$C$9,($C$24*($C$22*M48+$C$23*M49))),($C$24*($C$22*M48+$C$23*M49))) -> 955.69539 | M48: =$C$8+IF(M33>$C$15,MAX(M33*$C$9,($C$24*($C$22*N48+$C$23*N49))),($C$24*($C$22*N48+$C$23*N49))) -> 981.74407 | N48: =$C$8+MAX(N33*$C$9,1000) -> 1008.75
...

Sheet Volatility
B1: CYTK Volatility Computation
B2: Date | C2: Adj Close | D2: Delta | F2: Standard Dev | G2: Volatility | I2: Total Days | J2: 365
B3: 46178 | C3: 71.48 | F3: =_xlfn.STDEV.S(D3:D1258) -> 0.040243331 | G3: =F3*J3^0.5 -> 0.63884308 | I3: Working Days | J3: 252
B4: 46177 | C4: 72.29 | D4: =IFERROR(LN(C3/C4),"") -> -0.011268117
B5: 46176 | C5: 70.71 | D5: =IFERROR(LN(C4/C5),"") -> 0.022098801
B6: 46175 | C6: 70.91 | D6: =IFERROR(LN(C5/C6),"") -> -0.0028244617
B7: 46174 | C7: 73.68 | D7: =IFERROR(LN(C6/C7),"") -> -0.038319925
B8: 46171 | C8: 76.76 | D8: =IFERROR(LN(C7/C8),"") -> -0.040952279
B9: 46170 | C9: 76.81 | D9: =IFERROR(LN(C8/C9),"") -> -0.00065116887
B10: 46169 | C10: 77.15 | D10: =IFERROR(LN(C9/C10),"") -> -0.0044167388
B11: 46168 | C11: 76.29 | D11: =IFERROR(LN(C10/C11),"") -> 0.011209711
B12: 46164 | C12: 76.94 | D12: =IFERROR(LN(C11/C12),"") -> -0.0084840292
B13: 46163 | C13: 78.06 | D13: =IFERROR(LN(C12/C13),"") -> -0.014451864
B14: 46162 | C14: 78.77 | D14: =IFERROR(LN(C13/C14),"") -> -0.009054452
B15: 46161 | C15: 76.45 | D15: =IFERROR(LN(C14/C15),"") -> 0.029895281
... B1258: 44354 | C1258: 22.33 | D1258: =IFERROR(LN(C1257/C1258),"") -> -0.027697571

Sheet Key Financials
B1: CYTK Key Financials
B3: Income Statement | C3: USD Mn
C4: FY 2024 | D4: FY 2025 | E4: TTM Mar 2026 | F4: Note
B5: Total Revenue | C5: =18474/(10^3) -> 18.474 | D5: =88039/(10^3) -> 88.039 | E5: =105815/(10^3) -> 105.815 | F5: Includes collaboration revenue. Aficamten product rev: $4.8M Q1 2026 only.
B6: EBITDA | C6: =-527117/(10^3) -> -527.117 | D6: =-607733/(10^3) -> -607.733 | E6: =-634642/(10^3) -> -634.642 | F6: EBITDA margin -708% TTM
B7: EBIT | C7: =-536648/(10^3) -> -536.648 | D7: =-617858/(10^3) -> -617.858 | E7: =-645845/(10^3) -> -645.845 | F7: Used for EBIT/Interest metric in Sep 2025 scorecard
B8: Operating Cash Flow | C8: =-395890/(10^3) -> -395.89 | D8: =-510009/(10^3) -> -510.009 | E8: =-523849/(10^3) -> -523.849 | F8: Cash burn $524M/yr → ~17-month runway
B10: Balance Sheet | C10: USD Mn
C11: FY 2024 | D11: FY 2025 | E11: TTM Mar 2026 | F11: Note
B12: Cash | C12: 0 | D12: 0 | E12: 755.9 | F12: Per Q1 2026 8-K
B13: Financial Debt | C13: 0 | D13: 888 | E13: 888 | F13: 2031 notes $750M + residual 2027 ~$138M
B14: Net Debt | C14: 0 | D14: 0 | E14: 132 | F14: $888M − $755.9M · Used in RCF/Net Debt metric
B15: Total Assets | C15: =1401673/(10^3) -> 1401.673 | D15: =1424537/(10^3) -> 1424.537 | E15: =1273478/(10^3) -> 1273.478
B16: Total Equity | C16: =-135372/(10^3) -> -135.372 | D16: =-659625/(10^3) -> -659.625 | E16: =-826568/(10^3) -> -826.568
B18: RCF / Net Debt
B19: Retained Cash Flow (RCF = OCF − dividends) | C19: -523.8
B20: Net Debt (financial debt face − cash) | C20: 132
B21: RCF / Net Debt | C21: =C19/C20 -> -3.9681818

Sheet Credit Rating
B1: CYTK Implied Credit Rating · Moody's Pharmaceutical Scorecard
B2: Source: Moody's Ratings 'Rating Methodology: Pharmaceuticals' (September 15, 2025) · Report No. 1439384
B3: SCORECARD | L3: Rating | M3: Numeric Score
B4: Factor | C4: Wt | D4: Moody's B | E4: Moody's Caa | F4: Moody's Ca | G4: CYTK (TTM Mar 2026) | H4: Score | I4: Points | J4: Source | L4: Aaa | M4: 1
B5: Revenue ($B) | C5: 0.25 | D5: B: $1–$3B | E5: Caa: $0.25–$1B | F5: Ca: <$0.25B | G5: ='Key Financials'!E5/10^3 -> 0.105815 | H5: Ca | I5: =_xlfn.XLOOKUP(H5,$L$4:$L$11,$M$4:$M$11,"",0)*C5 -> 5 | J5: TTM Financials | L5: Aa | M5: 3
B6: Product & Therapeutic Diversity | C6: 0.1 | D6: B: Top 3 > 60% rev | E6: Caa: Top 3 > 70% | F6: Ca: Reliant on 1 product | G6: Single product: MYQORZO (aficamten / HCM) | H6: Ca | I6: =_xlfn.XLOOKUP(H6,$L$4:$L$11,$M$4:$M$11,"",0)*C6 -> 2 | L6: A | M6: 6
B7: Geographic Diversity | C7: 0.1 | D7: B: 75–90% one region | E7: Caa: >90% (diverse payors) | F7: Ca: >90% + limited payors | G7: US only; >95% US rev; Diverse Payors | H7: Caa | I7: =_xlfn.XLOOKUP(H7,$L$4:$L$11,$M$4:$M$11,"",0)*C7 -> 1.8 | J7: CYTK Q1 2026 8-K US = diverse payor market → Caa not Ca | L7: Baa | M7: 9
B8: Patent Exposures | C8: 0.1 | D8: B: At risk >30% (3 yrs) | E8: Caa: At risk >40% | F8: Ca: At risk >50% | G8: No ANDA challenges Aficamten IP past 2031 | H8: Ba | I8: =_xlfn.XLOOKUP(H8,$L$4:$L$11,$M$4:$M$11,"",0)*C8 -> 1.2 | J8: CYTK 2025 10-K | L8: Ba | M8: 12
B9: Pipeline Quality | C9: 0.1 | D9: B: Peak sales <10% of current revenue | E9: Caa: Peak sales <5% | F9: Ca: No late-stage pipeline | G9: omecamtiv mecarbil (Phase 3, HF) | H9: B | I9: =_xlfn.XLOOKUP(H9,$L$4:$L$11,$M$4:$M$11,"",0)*C9 -> 1.5 | J9: CYTK pipeline disclosures; Q1 2026 earnings call | L9: B | M9: 15
B10: Debt / EBITDA | C10: 0.1 | D10: B: 4.5–6x | E10: Caa: 6–9x | F10: Ca: >9x | G10: EBITDA $(634.6M) TTM Negative → not calculable | H10: Ca | I10: =_xlfn.XLOOKUP(H10,$L$4:$L$11,$M$4:$M$11,"",0)*C10 -> 2 | L10: Caa | M10: 18
B11: RCF / Net Debt | C11: 0.05 | D11: B: 0–5% | E11: Caa: <0% | F11: Ca: <(5)% | G11: ='Key Financials'!C21 -> -3.9681818 | H11: Ca | I11: =_xlfn.XLOOKUP(H11,$L$4:$L$11,$M$4:$M$11,"",0)*C11 -> 1 | L11: Ca | M11: 20
B12: EBIT / Interest Expense | C12: 0.05 | D12: B: 1–2.25x | E12: Caa: 0.5–1x | F12: Ca: <0.5x | G12: =-645.8/68.56 -> -9.4194866 | H12: Ca | I12: =_xlfn.XLOOKUP(H12,$L$4:$L$11,$M$4:$M$11,"",0)*C12 -> 1 | J12: EBIT $(645,845)K TTM Interest exp $68.56M
B13: Financial Policy | C13: 0.15 | D13: B: Favors shareholders; high financial risk | E13: Caa: Elevated restructuring risk | F13: Ca: Very elevated risk | G13: No dividend; no buybacks Conservative management | H13: Ba | I13: =_xlfn.XLOOKUP(H13,$L$4:$L$11,$M$4:$M$11,"",0)*C13 -> 1.8
B14: Aggregate Numeric Score = 17.30 | I14: =SUM(I5:I13) -> 17.3 | J14: Per Exhibit 5 (Rating methodology): 16.5 < x ≤ 17.5 → Caa1
B16: LIQUIDITY OVERRIDE · Excess Cash Balances (p.13)
B17: Cash ($M) | C17: 755.9 | I17: Q1 2026 8-K · Moody's Sep 2025, p.13: 'Large cash holdings provide buffers against credit deterioration'
B18: Financial Debt Face Value($M) | C18: 888 | I18: 2031 notes $750M + residual 2027 notes ~$138M
B19: Net Debt ($M) | C19: =C18-C17 -> 132.1
B20: Cash Burn (TTM) | C20: $(523.8M) | I20: ~17-month runway at current rate. Forward burn decreases as aficamten scales.
B21: Scorecard-Indicated | C21: Caa1 (score 17.30)
B22: IMPLIED RATING | C22: B3 / B2 | I22: 1–2 notch uplift for exceptional liquidity ($755.9M cash vs $132M net debt)
B24: Note :
B25: CYTK's scorecard metrics are poor because aficamten launched in January 2026 and the company is in its first year of commercialisation. The Caa1 raw score reflects that but not imminent default risk. With $755.9M cash and $132M net debt, CYTK can sustain current burn for over a year while aficamten scales. Moody's September 2025 methodology (p.13) explicitly recognises excess cash as a ratings consideration outside the scorecard. One to two notch uplift to B3/B2 reflects the time the balance sheet buys, not an endorsement of the current financials.
B53: https://fred.stlouisfed.org/series/BAMLH0A2HYB

Sheet Comps 
B2: Comparable Companies | C2: Ticker | D2: Credit Rating | E2: Company Overview | F2: Primary Rating Sources & Report Dates
B3: Gilead Sciences | C3: GILD | D3: A- (S&P)A3 (Moody's) | E3: A biopharmaceutical giant heavily dominant in antiviral therapeutics, specifically pioneering treatments for HIV, Hepatitis B, Hepatitis C, and COVID-19 (remdesivir), while expanding into oncology. | F3: S&P Global Ratings: "Gilead Sciences Inc.'s Proposed Senior Unsecured Debt Rated 'A-'" (May 14, 2026)Moody's Investors Service: "Moody's Ratings assigns A3 rating to Gilead's notes" (May 14, 2026)
B4: Amgen | C4: AMGN | D4: BBB+ (S&P) | E4: One of the world's largest independent biotech pioneers, focusing on human therapeutics across oncology, nephrology, cardiology, and inflammation, with major biologic blockbusters like Enbrel and Prolia. | F4: S&P Global Ratings: "Amgen Inc. Downgraded To 'BBB+' From 'A-'" (Dec 12, 2022) — Affirmed March 24, 2025
B5: Regeneron Pharmaceuticals | C5: REGN | D5: BBB+ (S&P) | E5: A fully integrated biopharmaceutical firm that discovers, invents, develops, and commercializes medicines for serious medical conditions, notably eye diseases (Eylea), allergic/inflammatory diseases (Dupixent), and cancer. | F5: S&P Global Ratings: "Regeneron Pharmaceuticals Inc. Assigned 'BBB+' Issuer Credit Rating; Outlook Stable" (Aug 5, 2020)
B6: Biogen | C6: BIIB | D6: Baa2 (Moody's) | E6: A specialized biopharmaceutical company deeply focused on neurodegenerative diseases, neurovascular disorders, and specialized immunology, known for its multiple sclerosis franchise and Alzheimer's disease treatments. | F6: Moody's Investors Service: "Rating Action: Moody's downgrades Biogen to Baa2; negative outlook" (Apr 11, 2022) — Affirmed March 5, 2024
B7: Vertex Pharmaceuticals | C7: VRTX | D7: BBB+ (S&P) | E7: A global biotechnology company that invests in scientific innovation to create transformative medicines for people with serious diseases, holding a near-monopoly on treatments for cystic fibrosis (CF) alongside expanding pipelines in gene editing. | F7: S&P Global Ratings: Public debt issuance ratings for senior unsecured notes.
B8: BioMarin Pharmaceutical | C8: BMRN | D8: BB+ (S&P / Fitch) | E8: A biotechnology company dedicated to developing and commercializing innovative therapies for patients with serious and life-threatening rare genetic diseases and medical conditions. | F8: S&P Global / Fitch: Standard high-yield corporate debt issuance ratings.
B10: #Note : These companies cannot be considered as exact comparables because CYTK only recently launched its first commercial product in January 2026; Hence we use build-up approach for determining the credit rating

Sheet References
