Workbook
Name Annual_Periods: OFFSET(#REF!,0,1):OFFSET(#REF!,0,-1)
Name BS_End: #REF!
Name BS_Start: #REF!
Name Comp_Name: [1]Assumptions!$B$2
Name Cost_of_Debt: [2]Assumptions!$B$15
Name Cost_of_Equity: [2]Assumptions!$B$22
Name Country_RP: [2]Assumptions!$B$19
Name Cur: [3]Input!$E$7
Name Current_Price: [1]Assumptions!$B$4
Name Cut_off: [3]Input!$E$3
Name DCF_Enterprise_Value: [1]DCF!$C$52
Name DCF_Enterprise_Value_PerShare: [1]DCF!$D$52
Name DCF_Equity_Value: [1]DCF!$C$54
Name DCF_Equity_Value_PerShare: [1]DCF!$D$54
Name Debt_Adj_Factor: [2]Assumptions!$B$13
Name Debt_MV: [2]Assumptions!$B$28
Name Equity_Beta: [2]Assumptions!$B$21
Name Equity_MV: [2]Assumptions!$B$27
Name Equity_Risk_Premium: [2]Assumptions!$B$18
Name g: [3]Input!$C$17
Name Risk_Free_Rate: [2]Assumptions!$B$12
Name Scale_Symbol: [1]Assumptions!$D$6
Name Scaler: [1]Assumptions!$C$6
Name Shares_Out: [2]Assumptions!$B$25
Name Size_RP: [2]Assumptions!$B$20
Name Tax_Rate: [2]Assumptions!$B$14
Name Terminal_Rate: [1]Assumptions!$B$34
Name Total_Capitalization: [2]Assumptions!$B$29
Name WACC: [2]Assumptions!$C$30
Name WACC_Override: [4]DCF!$K$21

Sheet Overview
B2: WAYSTAR HOLDING CORP. (NASDAQ: WAY) | VALUATION DATE: March 31, 2024
B3: A. Business Overview
B4: Waystar provides cloud-native software that automates healthcare revenue cycle management for US provider organizations. Its platform covers the full billing workflow: financial clearance, prior authorization, claims submission and monitoring, denial prevention and recovery, payer payment management, and patient collections. Core products include financial clearance, patient financial care and payment processing, claims and payer payment management, denials prevention and recovery, revenue capture, and analytics and reporting. The platform distributes through direct sales and integrations with leading EHR and practice management systems, serving hospitals, health systems, and ambulatory practices. Waystar earns revenue primarily on a subscription and per-transaction basis, with clients paying to process the claims volume flowing through their systems.

Sheet OPM
A1: Waystar Holding Corp. : Option Pricing Model (OPM) Equity Waterfall
A2: ASC 820 Level 3 Equity Allocation | Valuation Date: March 31, 2024 | Pre-IPO
A4: SECTION 1: KEY VALUATION INPUTS
A5: Valuation Date | B5: 45382
A6: IPO Date | B6: 45450
A7: Total Equity Value : Pre-money ($M) | B7: =2620*0+'Market Approach'!D24 -> 2818.3021 | G7: Multiples Approach
A8: Net Debt at March 31, 2024 ($M) | B8: =2218130/10^3 -> 2218.13 | G8: Source: Waystar S-1/A Cap Table. LT Debt ~$2,500M (First Lien + Second Lien) less cash ~$57M.
A9: Enterprise Value ($M) | B9: =B7+B8 -> 5036.4321
A10: Pre-IPO Shares Outstanding | B10: 121659634 | G10: https://www.sec.gov/Archives/edgar/data/1990354/000110465924065282/tm2333808-9_s1a.htm
A11: Options Outstanding (2019 Waystar Plan) | B11: 13670211 | G11: https://www.sec.gov/Archives/edgar/data/1990354/000110465924065282/tm2333808-9_s1a.htm
A12: Weighted Average Option Strike ($) | B12: 16.3 | G12: Source: S-1/A Dilution table. Wtd-avg exercise price $16.30/share.
A13: IPO Price; Validation Anchor ($) | B13: 21.5 | G13: Source: Waystar IPO June 7, 2024 @ $21.50/share. Goldman Sachs joint lead book-runner. Pitchbook
A14: Equity Value Per Pre-IPO Share | B14: =B7/B10*10^6 -> 23.165466
A16: SECTION 2: BLACK-SCHOLES INPUTS (OPM Call Spread Framework)
A17: Equity Value S ($M) | B17: =B7 -> 2818.3021
A18: Risk-Free Rate (rf) | B18: 0.0546 | G18: FRED Data as on March 31. 3M US Bond Yield
A19: Time to Liquidity : T (years) | B19: =68/365 -> 0.18630137 | G19: Valuation date March 31, 2024 to IPO June 7, 2024 = 68 days = 0.19 years. Short horizon reflects near-IPO status.
A20: Volatility : σ (peer-derived) | B20: ='Peer Volatility'!$R$10 -> 0.43998276
A22: SECTION 3: DERBY TOPCO LP CAP TABLE & BREAKPOINT ANALYSIS
A23: Derby TopCo Partnership LP held 100% of Waystar equity pre-IPO. LP interests converted to common at IPO via Equity Distribution, allocated per liquidation waterfall.
A24: Holder | B24: Pre-IPO Shares | C24: % Pre-IPO Equity | D24: Post-IPO % | E24: Shares (Post-IPO) | F24: Invested Capital ($M) | G24: Source
A25: EQT (Derby LuxCo S.à r.l.) | B25: 48653090 | C25: =B25/B10 -> 0.39991153 | D25: =E25/($B$10+45*10^6) -> 0.29193086 | E25: =B25 -> 48653090 | F25: 1350 | G25: Post-IPO 29.2% x 166,659,634. EQT lead; 2019 LBO entry $2.7B total equity. Schedule 13G.
A26: CPPIB | B26: 37183498 | C26: =B26/B10 -> 0.30563546 | D26: =E26/($B$10+45*10^6) -> 0.2231104 | E26: =B26 -> 37183498 | F26: 880 | G26: Post-IPO 22.3% x 166,659,634. Co-investor with EQT at 2019 LBO. S-1/A Principal Stockholders.
A27: Bain Capital (BCPE Derby) | B27: 28014818 | C27: =B27/B10 -> 0.23027209 | D27: =E27/($B$10+45*10^6) -> 0.168096 | E27: =B27 -> 28014818 | F27: 390 | G27: Post-IPO 16.8% x 166,659,634. Rolled equity from pre-2019 Navicure/ZirMed ownership. S-1/A.
A28: Management & Other LP holders | B28: 7108228 | C28: =B28/B10 -> 0.058427169 | D28: =E28/($B$10+45*10^6) -> 0.042651168 | E28: =B28 -> 7108228 | F28: 72 | G28: Residual pre-IPO LP pool ~7.1M shares. Management equity from 2019 plan + rollovers.
A29: Total LP (pre-IPO) | B29: =SUM(B25:B28) -> 120959634 | C29: =B29/B10 -> 0.99424624 | F29: =SUM(F25:F28) -> 2692
A31: BREAKPOINT ANALYSIS for Derby TopCo LP Waterfall
A32: Breakpoint Description | B32: Breakpoint ($M) | C32: Incremental Value ($M) | D32: Allocated To | E32: Rationale | G32: Source
A33: BP1: Minimum (floor) | B33: 0 | C33: 0 | D33: All classes | E33: OPM starts at $0 equity floor call spread anchors here. | G33: OPM convention per AICPA Practice Aid.
A34: BP2: Preferred / LP Pref Return | B34: =F29 -> 2692 | C34: =B34-B33 -> 2692 | D34: All LP classes pro-rata | E34: $2,692M = LBO total invested equity (EQT+CPPIB+Bain+Mgmt). Below this, all value accrues to senior LP interests. | G34: CPP Investments newsroom; EQT AB press release Oct 2019. $2.7B deal equity split ~$2,692M LP invested capital.
A35: BP3: Common Residual | B35: ∞ | C35: Residual | D35: All LP classes pro-rata | E35: Above BP2, incremental equity shared pro-rata by all LP holders. No separate preferred return structure disclosed in S-1/A; single-class OPM appropriate. | G35: S-1/A Basis of Presentation confirms single equity class (common stock) post-IPO.
A37: SECTION 4: BLACK-SCHOLES CALL VALUES PER BREAKPOINT
A38: OPM allocates equity value using call spread: C(Ki) - C(Ki+1), where C(K) = BSM call with equity value S, strike K, volatility σ, time T, risk-free rate rf.
A39: Parameter | B39: BP1: K = $0 | C39: BP2: K = $2,692M
A40: Strike K ($M) | B40: 0 | C40: =$B$34 -> 2692
A41: d1 | B41: N/A (K=0; C(0)=S) | C41: =(LN($B$17/$B$34)+($B$18+0.5*$B$20^2)*$B$19)/($B$20*SQRT($B$19)) -> 0.38995059
A42: d2 | B42: N/A (K=0; C(0)=S) | C42: =C41-B20*SQRT(B19) -> 0.20004241
A43: N(d1) | B43: 1 | C43: =NORMSDIST(C41) -> 0.65171346
A44: N(d2) | B44: 1 | C44: =NORMSDIST(C42) -> 0.57927629
A45: Call Value C(K) ($M) | B45: =$B$17 -> 2818.3021 | C45: =$B$17*C43-$C$40*EXP(-$B$18*$B$19)*C44 -> 293.09564
...

Sheet Peer Volatility
B2: Date | C2: NAS:RCM | E2: NYSE:VEEV | G2: NYSE:DOCS | I2: NAS:DH | K2: NAS:HQY
B3: Date | C3: Adj Close | D3: Delta | E3: Adj Close | F3: Delta | G3: Adj Close | H3: Delta | I3: Adj Close | J3: Delta | K3: Adj Close | L3: Delta
B4: 45379 | C4: 12.88 | E4: 231.69 | G4: 26.91 | I4: 8.07 | K4: 81.63 | N4: Company | O4: Standard Dev | P4: Volatility | Q4: Switch | R4: Volatility | T4: Total Days | U4: 365
B5: 45378 | C5: 13 | D5: =IFERROR(LN(C4/C5),"") -> -0.0092736368 | E5: 233.39 | F5: =IFERROR(LN(E4/E5),"") -> -0.0073106028 | G5: 26.99 | H5: =IFERROR(LN(G4/G5),"") -> -0.0029684623 | I5: 7.91 | J5: =IFERROR(LN(I4/I5),"") -> 0.020025701 | K5: 79.72 | L5: =IFERROR(LN(K4/K5),"") -> 0.023676346 | N5: NAS:RCM | O5: =_xlfn.STDEV.S(D5:D252) -> 0.030786414 | P5: =O5*$U$5^0.5 -> 0.48871918 | Q5: 1 | R5: =IF(Q5=1,P5,"") -> 0.48871918 | T5: Working Days | U5: 252
B6: 45377 | C6: 13 | D6: =IFERROR(LN(C5/C6),"") -> 0 | E6: 232.68 | F6: =IFERROR(LN(E5/E6),"") -> 0.003046755 | G6: 26.99 | H6: =IFERROR(LN(G5/G6),"") -> 0 | I6: 7.78 | J6: =IFERROR(LN(I5/I6),"") -> 0.016571444 | K6: 79.48 | L6: =IFERROR(LN(K5/K6),"") -> 0.0030150777 | N6: NYSE:VEEV | O6: =_xlfn.STDEV.S(F5:F252) -> 0.022155777 | P6: =O6*$U$5^0.5 -> 0.35171206 | Q6: 1 | R6: =IF(Q6=1,P6,"") -> 0.35171206
B7: 45376 | C7: 13.06 | D7: =IFERROR(LN(C6/C7),"") -> -0.0046047664 | E7: 229.42 | F7: =IFERROR(LN(E6/E7),"") -> 0.014109734 | G7: 26.91 | H7: =IFERROR(LN(G6/G7),"") -> 0.0029684623 | I7: 7.86 | J7: =IFERROR(LN(I6/I7),"") -> -0.010230268 | K7: 79.38 | L7: =IFERROR(LN(K6/K7),"") -> 0.0012589703 | N7: NYSE:DOCS | O7: =_xlfn.STDEV.S(H5:H252) -> 0.029662813 | P7: =O7*$U$5^0.5 -> 0.47088256 | Q7: 1 | R7: =IF(Q7=1,P7,"") -> 0.47088256
B8: 45373 | C8: 13 | D8: =IFERROR(LN(C7/C8),"") -> 0.0046047664 | E8: 230.42 | F8: =IFERROR(LN(E7/E8),"") -> -0.0043493458 | G8: 27.64 | H8: =IFERROR(LN(G7/G8),"") -> -0.026766034 | I8: 7.61 | J8: =IFERROR(LN(I7/I8),"") -> 0.032323435 | K8: 79.63 | L8: =IFERROR(LN(K7/K8),"") -> -0.0031444589 | N8: NAS:DH | O8: =_xlfn.STDEV.S(J5:J252) -> 0.034634054 | P8: =O8*$U$5^0.5 -> 0.54979856 | Q8: 1 | R8: =IF(Q8=1,P8,"") -> 0.54979856
B9: 45372 | C9: 13.1 | D9: =IFERROR(LN(C8/C9),"") -> -0.0076628727 | E9: 231.82 | F9: =IFERROR(LN(E8/E9),"") -> -0.0060574779 | G9: 28.02 | H9: =IFERROR(LN(G8/G9),"") -> -0.013654542 | I9: 7.91 | J9: =IFERROR(LN(I8/I9),"") -> -0.03866461 | K9: 82.2 | L9: =IFERROR(LN(K8/K9),"") -> -0.031764396 | N9: NAS:HQY | O9: =_xlfn.STDEV.S(L5:L252) -> 0.021342484 | P9: =O9*$U$5^0.5 -> 0.33880143 | Q9: 1 | R9: =IF(Q9=1,P9,"") -> 0.33880143
B10: 45371 | C10: 13.15 | D10: =IFERROR(LN(C9/C10),"") -> -0.0038095284 | E10: 230.17 | F10: =IFERROR(LN(E9/E10),"") -> 0.0071430421 | G10: 28.49 | H10: =IFERROR(LN(G9/G10),"") -> -0.016634608 | I10: 8.02 | J10: =IFERROR(LN(I9/I10),"") -> -0.01381064 | K10: 81.36 | L10: =IFERROR(LN(K9/K10),"") -> 0.01027155 | N10: Average Volatility | P10: =AVERAGE(P5:P9) -> 0.43998276 | R10: =AVERAGE(R5:R9) -> 0.43998276
B11: 45370 | C11: 13.09 | D11: =IFERROR(LN(C10/C11),"") -> 0.0045731787 | E11: 229.95 | F11: =IFERROR(LN(E10/E11),"") -> 0.00095627235 | G11: 28.48 | H11: =IFERROR(LN(G10/G11),"") -> 0.00035106197 | I11: 7.85 | J11: =IFERROR(LN(I10/I11),"") -> 0.02142489 | K11: 83.53 | L11: =IFERROR(LN(K10/K11),"") -> -0.026322097
B12: 45369 | C12: 13.17 | D12: =IFERROR(LN(C11/C12),"") -> -0.0060929358 | E12: 228.43 | F12: =IFERROR(LN(E11/E12),"") -> 0.0066320763 | G12: 27.88 | H12: =IFERROR(LN(G11/G12),"") -> 0.021292501 | I12: 8.05 | J12: =IFERROR(LN(I11/I12),"") -> -0.02515856 | K12: 82.96 | L12: =IFERROR(LN(K11/K12),"") -> 0.0068472848
B13: 45366 | C13: 13.52 | D13: =IFERROR(LN(C12/C13),"") -> -0.026228555 | E13: 226.98 | F13: =IFERROR(LN(E12/E13),"") -> 0.0063679098 | G13: 27.88 | H13: =IFERROR(LN(G12/G13),"") -> 0 | I13: 7.89 | J13: =IFERROR(LN(I12/I13),"") -> 0.020075957 | K13: 81.44 | L13: =IFERROR(LN(K12/K13),"") -> 0.018492011
B14: 45365 | C14: 13.67 | D14: =IFERROR(LN(C13/C14),"") -> -0.01103358 | E14: 232.47 | F14: =IFERROR(LN(E13/E14),"") -> -0.023899277 | G14: 27.85 | H14: =IFERROR(LN(G13/G14),"") -> 0.0010766195 | I14: 8.09 | J14: =IFERROR(LN(I13/I14),"") -> -0.025032596 | K14: 82.02 | L14: =IFERROR(LN(K13/K14),"") -> -0.0070965672
B15: 45364 | C15: 13.95 | D15: =IFERROR(LN(C14/C15),"") -> -0.020275858 | E15: 234.79 | F15: =IFERROR(LN(E14/E15),"") -> -0.0099303132 | G15: 27.9 | H15: =IFERROR(LN(G14/G15),"") -> -0.0017937225 | I15: 8.185 | J15: =IFERROR(LN(I14/I15),"") -> -0.01167448 | K15: 82.71 | L15: =IFERROR(LN(K14/K15),"") -> -0.0083773937
B16: 45363 | C16: 14.04 | D16: =IFERROR(LN(C15/C16),"") -> -0.0064308903 | E16: 231.05 | F16: =IFERROR(LN(E15/E16),"") -> 0.01605736 | G16: 27.66 | H16: =IFERROR(LN(G15/G16),"") -> 0.0086393626 | I16: 8.22 | J16: =IFERROR(LN(I15/I16),"") -> -0.0042669982 | K16: 82.14 | L16: =IFERROR(LN(K15/K16),"") -> 0.0069154052
B17: 45362 | C17: 14.04 | D17: =IFERROR(LN(C16/C17),"") -> 0 | E17: 227.75 | F17: =IFERROR(LN(E16/E17),"") -> 0.014385601 | G17: 27.7 | H17: =IFERROR(LN(G16/G17),"") -> -0.001445087 | I17: 8.37 | J17: =IFERROR(LN(I16/I17),"") -> -0.018083675 | K17: 81.96 | L17: =IFERROR(LN(K16/K17),"") -> 0.0021937852
B18: 45359 | C18: 13.88 | D18: =IFERROR(LN(C17/C18),"") -> 0.011461444 | E18: 227.79 | F18: =IFERROR(LN(E17/E18),"") -> -0.00017561575 | G18: 27.91 | H18: =IFERROR(LN(G17/G18),"") -> -0.0075526344 | I18: 8.48 | J18: =IFERROR(LN(I17/I18),"") -> -0.013056565 | K18: 81.09 | L18: =IFERROR(LN(K17/K18),"") -> 0.010671674
B19: 45358 | C19: 14.19 | D19: =IFERROR(LN(C18/C19),"") -> -0.022088536 | E19: 230.17 | F19: =IFERROR(LN(E18/E19),"") -> -0.010394014 | G19: 28.69 | H19: =IFERROR(LN(G18/G19),"") -> -0.027563582 | I19: 8.38 | J19: =IFERROR(LN(I18/I19),"") -> 0.011862535 | K19: 80.32 | L19: =IFERROR(LN(K18/K19),"") -> 0.009540993
B20: 45357 | C20: 13.93 | D20: =IFERROR(LN(C19/C20),"") -> 0.018492703 | E20: 224.56 | F20: =IFERROR(LN(E19/E20),"") -> 0.024675234 | G20: 28.11 | H20: =IFERROR(LN(G19/G20),"") -> 0.020423245 | I20: 8.14 | J20: =IFERROR(LN(I19/I20),"") -> 0.029057734 | K20: 80.55 | L20: =IFERROR(LN(K19/K20),"") -> -0.0028594537
B21: 45356 | C21: 13.97 | D21: =IFERROR(LN(C20/C21),"") -> -0.0028673855 | E21: 221.64 | F21: =IFERROR(LN(E20/E21),"") -> 0.013088488 | G21: 27.74 | H21: =IFERROR(LN(G20/G21),"") -> 0.01324997 | I21: 8.35 | J21: =IFERROR(LN(I20/I21),"") -> -0.025471359 | K21: 81.05 | L21: =IFERROR(LN(K20/K21),"") -> -0.0061881386
B22: 45355 | C22: 13.99 | D22: =IFERROR(LN(C21/C22),"") -> -0.0014306154 | E22: 226 | F22: =IFERROR(LN(E21/E22),"") -> -0.019480555 | G22: 28.63 | H22: =IFERROR(LN(G21/G22),"") -> -0.031579704 | I22: 8.92 | J22: =IFERROR(LN(I21/I22),"") -> -0.066034408 | K22: 82.38 | L22: =IFERROR(LN(K21/K22),"") -> -0.016276441
... B252: 45019 | C252: 14.7 | D252: =IFERROR(LN(C251/C252),"") -> 0.02684725 | E252: 181.11 | F252: =IFERROR(LN(E251/E252),"") -> 0.0017102037 | G252: 31.49 | H252: =IFERROR(LN(G251/G252),"") -> 0.0050681135 | I252: 10.16 | J252: =IFERROR(LN(I251/I252),"") -> 0.0039292781 | K252: 57.33 | L252: =IFERROR(LN(K251/K252),"") -> -0.025259667

Sheet Market Approach
B2: WAYSTAR HOLDING CORP. (NASDAQ: WAY) | VALUATION DATE: March 31, 2024
B4: NAS:WAY | C4: Waystar | E4: =824719/(10^3) -> 824.719 | F4: =343753/(10^3) -> 343.753 | G4: =F4/E4 -> 0.41681227 | L4: USD Mn
B5: Ticker | C5: Company | D5: EV | E5: Revenue | F5: EBITDA | G5: EBITDA Margin(%) | H5: EV/Revenue (X) | I5: EV/EBITDA (X) | J5: Selection | K5: EV/Revenue (X) | L5: EV/EBITDA (X)
B6: ='Comps Set'!B5 -> NAS:RCM | C6: ='Comps Set'!C5 -> R1 RCM | D6: =6128411/(10^3) -> 6128.411 | E6: =2312500/(10^3) -> 2312.5 | F6: =624300/(10^3) -> 624.3 | G6: =F6/E6 -> 0.26996757 | H6: =D6/E6 -> 2.6501237 | I6: =D6/F6 -> 9.816452 | J6: 1 | K6: =IF($J6=1,H6,"") -> 2.6501237 | L6: =IF($J6=1,I6,"") -> 9.816452
B7: ='Comps Set'!B6 -> NYSE:PHR | C7: ='Comps Set'!C6 -> Phreesia | D7: =1185707/(10^3) -> 1185.707 | E7: =373671/(10^3) -> 373.671 | F7: =-17513/(10^3) -> -17.513 | G7: =F7/E7 -> -0.046867432 | H7: =D7/E7 -> 3.1731309 | I7: =D7/F7 -> -67.704391 | J7: Neg EBITDA | K7: =IF($J7=1,H7,"") | L7: =IF($J7=1,I7,"")
B8: ='Comps Set'!B7 -> NYSE:EVH | C8: ='Comps Set'!C7 -> Evolent Health | D8: =4444659/(10^3) -> 4444.659 | E8: =2353868/(10^3) -> 2353.868 | F8: =202816/(10^3) -> 202.816 | G8: =F8/E8 -> 0.08616286 | H8: =D8/E8 -> 1.8882363 | I8: =D8/F8 -> 21.914736 | J8: Outlier | K8: =IF($J8=1,H8,"") | L8: =IF($J8=1,I8,"")
B9: ='Comps Set'!B8 -> NAS:HCAT | C9: ='Comps Set'!C8 -> Health Catalyst | D9: =386045/(10^3) -> 386.045 | E9: =296793/(10^3) -> 296.793 | F9: =12536/(10^3) -> 12.536 | G9: =F9/E9 -> 0.042238193 | H9: =D9/E9 -> 1.3007214 | I9: =D9/F9 -> 30.794911 | J9: Outlier | K9: =IF($J9=1,H9,"") | L9: =IF($J9=1,I9,"")
B10: ='Comps Set'!B9 -> NYSE:VEEV | C10: ='Comps Set'!C9 -> Veeva Systems | D10: =32925272/(10^3) -> 32925.272 | E10: =2487693/(10^3) -> 2487.693 | F10: =1135648/(10^3) -> 1135.648 | G10: =F10/E10 -> 0.45650649 | H10: =D10/E10 -> 13.235263 | I10: =D10/F10 -> 28.992498 | J10: 1 | K10: =IF($J10=1,H10,"") -> 13.235263 | L10: =IF($J10=1,I10,"") -> 28.992498
B11: ='Comps Set'!B10 -> NYSE:DOCS | C11: ='Comps Set'!C10 -> Doximity | D11: =4500340/(10^3) -> 4500.34 | E11: =475422/(10^3) -> 475.422 | F11: =230249/(10^3) -> 230.249 | G11: =F11/E11 -> 0.48430447 | H11: =D11/E11 -> 9.4659902 | I11: =D11/F11 -> 19.545535 | J11: 1 | K11: =IF($J11=1,H11,"") -> 9.4659902 | L11: =IF($J11=1,I11,"") -> 19.545535
B12: ='Comps Set'!B11 -> NAS:DH | C12: ='Comps Set'!C11 -> Definitive Healthcare | D12: =1250056/(10^3) -> 1250.056 | E12: =255694/(10^3) -> 255.694 | F12: =40596/(10^3) -> 40.596 | G12: =F12/E12 -> 0.1587679 | H12: =D12/E12 -> 4.888875 | I12: =D12/F12 -> 30.79259 | J12: 1 | K12: =IF($J12=1,H12,"") -> 4.888875 | L12: =IF($J12=1,I12,"") -> 30.79259
B13: ='Comps Set'!B12 -> NAS:TBRG | C13: ='Comps Set'!C12 -> TruBridge | D13: =334541/(10^3) -> 334.541 | E13: =334848/(10^3) -> 334.848 | F13: =41038/(10^3) -> 41.038 | G13: =F13/E13 -> 0.1225571 | H13: =D13/E13 -> 0.99908317 | I13: =D13/F13 -> 8.1519811 | J13: 1 | K13: =IF($J13=1,H13,"") -> 0.99908317 | L13: =IF($J13=1,I13,"") -> 8.1519811
B14: ='Comps Set'!B13 -> NAS:HQY | C14: ='Comps Set'!C13 -> HealthEquity | D14: =7637968/(10^3) -> 7637.968 | E14: =1042752/(10^3) -> 1042.752 | F14: =393114/(10^3) -> 393.114 | G14: =F14/E14 -> 0.37699664 | H14: =D14/E14 -> 7.3248174 | I14: =D14/F14 -> 19.429397 | J14: 1 | K14: =IF($J14=1,H14,"") -> 7.3248174 | L14: =IF($J14=1,I14,"") -> 19.429397
B15: Mean | K15: =AVERAGE(K6:K14) -> 6.4273588 | L15: =AVERAGE(L6:L14) -> 19.454742
B16: Median | K16: =MEDIAN(K6:K14) -> 6.1068462 | L16: =MEDIAN(L6:L14) -> 19.487466
B17: Source : Pitchbook
E18: USD Mn
C19: Particulars | D19: EV/Revenue | E19: EV/EBITDA
C20: Revenue (TTM) | D20: =E4 -> 824.719 | E20: =F4 -> 343.753
C21: Implied EV (Median Multiple) | D21: =D20*K16 -> 5036.4321 | E21: =E20*L16 -> 6698.875
C22: Add: Cash and Cash Equivalents | D22: =57337/10^3 -> 57.337 | E22: =57337/10^3 -> 57.337
C23: Less : Debt and Debt Equivalents | D23: =-2275467/10^3 -> -2275.467 | E23: =-2275467/10^3 -> -2275.467
C24: Equity Value | D24: =SUM(D21:D23) -> 2818.3021 | E24: =SUM(E21:E23) -> 4480.745
C25: Shares Outstanding | D25: =OPM!$B$10 -> 121659634 | E25: =OPM!$B$10 -> 121659634
C26: Per Share Value | D26: =D24*10^6/D25 -> 23.165466 | E26: =E24*10^6/E25 -> 36.83017
B29: Note : | C29: Adopted EV/Revenue approach because most comps have a relatively low EBITDA margin, inflating the EV/EBITDA multiple, and Waystar has a its EBITDA margin in the upper quartile of the set, hence the EV derived using EV/EBITDA margin is inflated

Sheet Comps Set
B2: WAYSTAR HOLDING CORP. (NASDAQ: WAY) | VALUATION DATE: March 31, 2024
B4: Ticker | C4: Company | D4: Business Description
B5: NAS:RCM | C5: R1 RCM | D5: End-to-end RCM automation platform for hospitals, health systems, and physician groups. Automates pre-registration, coding, claims submission, denial management, and underpayment recovery. Closest structural peer to Waystar. Taken private November 2024 -- still listed at March 28, 2024 valuation date.
B6: NYSE:PHR | C6: Phreesia | D6: Patient intake and access management platform for ambulatory practices. Handles eligibility verification, prior authorization, digital check-in, and patient payment collection at point of care. Directly overlaps with Waystar front-end clearance and patient financial engagement modules.
B7: NYSE:EVH | C7: Evolent Health | D7: Specialty care management and value-based care enablement. Manages medical cost for health plans in oncology, cardiology, and musculoskeletal through a technology platform and clinical services. More services-heavy and payer-facing than Waystar -- explains a margin and multiple discount.
B8: NAS:HCAT | C8: Health Catalyst | D8: Healthcare data and analytics platform serving health systems and academic medical centers. Provides a cloud-based data operating system with analytics applications for operational, clinical, and financial use cases. Same CFO buyer as Waystar. Core product is analytics, not payments automation.
B9: NYSE:VEEV | C9: Veeva Systems | D9: Life sciences vertical SaaS covering commercial, regulatory, clinical, and quality workflows for pharma and biotech. Not RCM but the canonical benchmark for mission-critical vertical SaaS with high NRR and strong pricing power. Anchors the premium end of the healthcare SaaS multiple range. Waystar warrants a discount given lower margins and smaller scale.
B10: NYSE:DOCS | C10: Doximity | D10: Digital platform for US physicians providing networking, telehealth, and workflow tools. Monetizes through SaaS subscriptions paid by pharma companies and health systems. High gross margins, strong NRR, capital-light model. Not RCM -- anchors the high-quality healthcare SaaS premium alongside Veeva.
B11: NAS:DH | C11: Definitive Healthcare | D11: Healthcare commercial intelligence platform providing data and analytics on providers and payers to life sciences companies and health IT vendors. SaaS subscription model. Overlaps on analytics dimension but serves a different buyer. Lower growth trajectory by March 2024 -- explains multiple discount.
B12: NAS:TBRG | C12: TruBridge | D12: RCM software and services for rural and community hospitals. Covers billing, coding, eligibility, and patient engagement bundled with outsourced services for smaller provider organizations. More services-heavy than Waystar with lower-acuity market focus -- drives a lower multiple. Closest lower-end RCM peer.
B13: NAS:HQY | C13: HealthEquity | D13: Health savings account administration and healthcare financial technology platform. Manages HSAs, FSAs, and HRAs for employers and health plans. Processes healthcare payments at the employer level rather than provider billing level. Adjacent to Waystar patient payment workflows -- anchors healthcare fintech end of the range.

Sheet References
